Workbook

Sheet Componentes
A1: Catálogo de Componentes — Design Engineering Center (DEC) UAI
A2: Fuente: https://dec.uai.cl/componentes/ · Extraído el 2026-09-25 · 209 componentes
A4: N° | B4: ID Sitio | C4: Familia | D4: Modelo | E4: Función | F4: Especificaciones
A5: =ROW()-4 | B5: 417 | C5: Baterías | D5: BRC 18650 battery 6800mah 3.7V Li-ion | E5: Baterías recargables de ion de litio (Li-ion) | F5: Voltaje nominal 3.7 V. Capacidad 6800 mAh
A6: =ROW()-4 | B6: 417 | C6: Baterías | D6: NCR 18650B Li-ion | E6: Baterías recargables de ion de litio (Li-ion) | F6: Voltaje nominal 3.6–3.7 V
A7: =ROW()-4 | B7: 418 | C7: Módulo | D7: XL6009 | E7: Regulador de voltaje | F7: Voltaje de entrada 3–32 V. Voltaje de salida hasta 35 V
A8: =ROW()-4 | B8: 422 | C8: Módulo | D8: HX-2S-A2 | E8: Cargador BMS 18650 2S 5A | F8: BMS para baterías Li-ion 2S. Corriente máxima 5 A. Voltaje de carga 8.4 V
A9: =ROW()-4 | B9: 648 | C9: Sensores | D9: SW-420 | E9: Vibración | F9: Voltaje de operación 3.3V/5.0 V. Salida digital: Nivel alto 1 - Nivel bajo 0
A10: =ROW()-4 | B10: 649 | C10: Sensores | D10: YG1006 IR | E10: Detectar presencia de fuego mediante radiación infrarroja | F10: Voltaje de operación 3.3 V/5.0 V. Temperatura de trabajo: -25°C a 85 °C
A11: =ROW()-4 | B11: 650 | C11: Sensores | D11: RFID-RC522 | E11: Lectura/escritura RFID | F11: Voltaje de operación 3.3 V. Distancia de lectura: 0 a 60mm.
A12: =ROW()-4 | B12: 651 | C12: Sensores | D12: AM2302 (DHT22) | E12: Humedad y temperatura | F12: Voltaje 3.3 V/6.0 V. Rango temp: -40°C a 80°C. Rango humedad: 0 a 100% RH
A13: =ROW()-4 | B13: 652 | C13: Sensores | D13: Fd10 (Fz0506) | E13: Nivel de agua | F13: Voltaje 3.3 V/5.0 V. Temperatura de trabajo : -30°C a 10°C. Análogo
A14: =ROW()-4 | B14: 653 | C14: Sensores | D14: HC-SR04 4 pines | E14: De distancia ultrasónico | F14: Voltaje 5.0 V. Ángulo del sensor: <15 grados. Rango distancia: 2 a 450 cm
A15: =ROW()-4 | B15: 654 | C15: Sensores | D15: MH-RD Raindrops module | E15: Presencia e intensidad de lluvia | F15: Voltaje 3.3 V/5.0 V. Señal análoga: Voltaje dependiente de humedad
A16: =ROW()-4 | B16: 655 | C16: Sensores | D16: MQ-3 | E16: Detector de Etanol | F16: Voltaje 5.0 V. Señal: Analógica (proporcional a la concentración)
... A117: =ROW()-4 | B117: 756 | C117: Componentes | D117: KY-009 | E117: LED SMD RGB | F117: Voltaje de operación 3.3 V/5.0 V
A118: =ROW()-4 | B118: 757 | C118: Componentes | D118: PCB modificadas | F118: Con cuatro interruptores
A119: =ROW()-4 | B119: 758 | C119: Componentes | D119: 3.5 inch RPI Display | E119: Pantalla touch LCD | F119: Voltaje de operación 5.0 V
A120: =ROW()-4 | B120: 759 | C120: Componentes | D120: NX3224T024 | E120: Pantalla touch LCD | F120: Tamaño 2.4 pulgadas. Voltaje 3.3 V/5.0 V
A121: =ROW()-4 | B121: 760 | C121: Componentes | D121: Shield TFT Touch | E121: Pantalla touch LCD | F121: Voltaje de operación 5.0 V
A122: =ROW()-4 | B122: 761 | C122: Componentes | D122: Microswitch V-156-1C25 | E122: 2 pines funciona como un interruptor simple de tipo ON/OFF (encendido/apagado) Interruptor de acción rápida | F122: Voltaje nominal 250 VAC
A123: =ROW()-4 | B123: 762 | C123: Componentes | D123: Battery Shield 18650 (Doble Pila) | E123: Fuente de alimentación portátil | F123: Voltaje de salida 5.0 V
A124: =ROW()-4 | B124: 763 | C124: Componentes | D124: Battery Shield 18650 (Una Pila) | E124: Fuente de alimentación portátil | F124: Voltaje de salida 5.0 V
A125: =ROW()-4 | B125: 764 | C125: Componentes | D125: VN-2252 | E125: Ventilador compacto | F125: Voltaje nominal 12 V. Dimensiones 40 × 40 × 20 mm
A126: =ROW()-4 | B126: 765 | C126: Componentes | D126: Botón Sanwa OBSF-24 | E126: Botón pulsador | F126: Diámetro 24 mm
A127: =ROW()-4 | B127: 766 | C127: Componentes | D127: AFC0612D | E127: Ventilador compacto | F127: Voltaje nominal 12 V. Dimensiones 60 × 60 × 25 mm
A128: =ROW()-4 | B128: 767 | C128: Componentes | D128: Botón Arcade 24mm | E128: Botón pulsador | F128: Diámetro 24 mm
A129: =ROW()-4 | B129: 768 | C129: Componentes | D129: Válvula solenoide | E129: Controla flujo de líquidos o gases | F129: Voltaje nominal 12 V
A130: =ROW()-4 | B130: 769 | C130: Componentes | D130: Brushless Fan Pengdalantu | E130: Ventilador compacto | F130: Voltaje nominal 5.0 V. Dimensiones 30 × 30 × 10 mm
... A144: =ROW()-4 | B144: 783 | C144: Componentes | D144: XH-M239 | E144: Probador de capacidad de baterías de litio | F144: Diseñado para baterías de litio 18650
A145: =ROW()-4 | B145: 784 | C145: Placas | D145: PCB con Arduino RedBeard
A146: =ROW()-4 | B146: 785 | C146: Placas | D146: Arduino UNO | E146: Prototipado y control básico de sistemas electrónicos | F146: Voltaje de operación 5.0 V. Microcontrolador ATmega328P
A147: =ROW()-4 | B147: 786 | C147: Placas | D147: ESP8266MOD | E147: Unicamente WIFI | F147: Voltaje de operación 3.3 V. Conectividad WiFi
A148: =ROW()-4 | B148: 787 | C148: Placas | D148: ESP32 | E148: Con Bluethooth y WIFI | F148: Voltaje de operación 3.3 V. Conectividad WiFi y Bluetooth
A149: =ROW()-4 | B149: 788 | C149: Placas | D149: Crowduino | E149: Placa compatible con Arduino UNO | F149: Voltaje de operación 5.0 V. Compatible con Arduino UNO
A150: =ROW()-4 | B150: 789 | C150: Placas | D150: Arduino Leonardo | E150: Permite conectarse al computador y funcionar como teclado o mouse | F150: Voltaje de operación 5.0 V. Microcontrolador ATmega32U4
A151: =ROW()-4 | B151: 790 | C151: Placas | D151: Arduino Pro Micro | E151: Emulación teclado/control/mouse compacta | F151: Voltaje de operación 5.0 V. Microcontrolador ATmega32U4
A152: =ROW()-4 | B152: 791 | C152: Placas | D152: Arduino Nano 33 Ble | E152: Proyectos IoT y wearables, Proyectos conectados por Bluetooth, como relojes o sensores | F152: Voltaje de operación 3.3 V. Conectividad Bluetooth Low Energy
A153: =ROW()-4 | B153: 792 | C153: Placas | D153: Arduino doc 2 | E153: WIFI, Equipo que conecta sensores a internet (Gateway IoT) | F153: Voltaje de operación 5.0 V
A154: =ROW()-4 | B154: 793 | C154: Placas | D154: Raspberry Pi Pico | E154: Flexible sin conectividad inalámbrica | F154: Voltaje de operación 3.3 V. Microcontrolador RP2040
...

Sheet Resumen por familia
A1: Resumen por familia
A3: Familia | B3: Cantidad de componentes | C3: % del total
A4: Baterías | B4: =COUNTIF(Componentes!$C$5:$C$213,A4) | C4: =B4/209
A5: Bomba | B5: =COUNTIF(Componentes!$C$5:$C$213,A5) | C5: =B5/209
A6: Cables | B6: =COUNTIF(Componentes!$C$5:$C$213,A6) | C6: =B6/209
A7: Celda de carga | B7: =COUNTIF(Componentes!$C$5:$C$213,A7) | C7: =B7/209
A8: Componentes | B8: =COUNTIF(Componentes!$C$5:$C$213,A8) | C8: =B8/209
A9: Kit | B9: =COUNTIF(Componentes!$C$5:$C$213,A9) | C9: =B9/209
A10: Motor | B10: =COUNTIF(Componentes!$C$5:$C$213,A10) | C10: =B10/209
A11: Módulo | B11: =COUNTIF(Componentes!$C$5:$C$213,A11) | C11: =B11/209
A12: Placas | B12: =COUNTIF(Componentes!$C$5:$C$213,A12) | C12: =B12/209
A13: Prototipado | B13: =COUNTIF(Componentes!$C$5:$C$213,A13) | C13: =B13/209
A14: Robot | B14: =COUNTIF(Componentes!$C$5:$C$213,A14) | C14: =B14/209
A15: Sensores | B15: =COUNTIF(Componentes!$C$5:$C$213,A15) | C15: =B15/209
A16: Total | B16: =SUM(B4:B15) | C16: =SUM(C4:C15)
